Workbook
Name __: #REF!
Name __1_2000년입출고: #REF!
Name __KEY2: #REF!
Name _0: #REF!
Name _1: #REF!
Name _1_2000년입출고: #REF!
Name _10H_0Print_Area: #REF!
Name _13R_0PA: #REF!
Name _16U_0PA: #REF!
Name _2: #REF!
Name _2C_0PA: #REF!
Name _3: #REF!
Name _3H_0PA: #REF!
Name _4: #REF!
Name _4C_0PA: #REF!
Name _4H_0Print_Area: #REF!
Name _6R_0PA: #REF!
Name _7H_0PA: #REF!
Name _7U_0PA: #REF!
Name _Fill: #REF!
Name _Key2: #REF!
Name _Sort: #REF!
Name A: #REF!
Name AAA: #REF!
Name Acquisition_Costs: #REF!
Name Adjusted_Basis: #REF!
Name Bal_EOY1_Mtg_1: #REF!
Name Bal_EOY1_Mtg_2: #REF!
Name Bal_EOY2_Mtg_1: #REF!
Name Bal_EOY2_Mtg_2: #REF!
Name Bal_EOY3_Mtg_1: #REF!
Name Bal_EOY3_Mtg_2: #REF!
Name Bal_EOY4_Mtg_1: #REF!
Name Bal_EOY4_Mtg_2: #REF!
Name Bal_EOY5_Mtg_1: #REF!
Name Bal_EOY5_Mtg_2: #REF!
Name BS: #REF!
Name BTL: #REF!
Name CFBT_APOD: #REF!
Name data: #REF!
Name Date: #REF!
Name dfakdf: #REF!
Name Down_Payment: #REF!
Name ERI_APOD: #REF!
Name file: #REF!
Name FKFK: #REF!
Name GOI: #REF!
Name GOI_APOD: #REF!
Name Initial_Investment: #REF!
Name INPUT: #REF!
Name Land_summary: 토지조서!$A$140:$AA$150
Name Leasing_Commissions: #REF!
Name Loan_Points: #REF!
Name Location: #REF!
Name mii: #REF!
Name ML: #REF!
Name Name: #REF!
Name NOI_APOD: #REF!
Name OP_EXP_APOD: #REF!
Name OTHER_APOD: #REF!

Sheet 건축개요
A1: 사 업 명
A4: ■ 건축개요
A5: 공 사 명 | C5: 래미안목동아델리체
A6: 대지위치 | C6: 서울 양천구 신정동 1326
A7: 지역지구 | C7: 도시지역, 제2종일반주거지역
A8: 공사종별 | C8: 아파트 | I8: =I9/$F$9 -> 0
A9: 대지면적 | C9: =F9-I9-L9 -> 60663.8 | D9: =C9*0.3025 -> 18350.8 | E9: 매입면적: | F9: 60663.8 | G9: =F9*0.3025 -> 18350.8 | H9: 기부채납면적 : | I9: 0 | J9: =I9*0.3025 -> 0
A10: 용 도 | C10: 공동주택, 근생시설
A11: 건축면적 | C11: 13572.54 | D11: =C11*0.3025 -> 4105.6934
A12: 건 폐 율 | C12: =C11/C9 -> 0.22373376 | D12: (법정 : | E12: 22.37 | F12: %)
A13: 연 면 적 | C13: =E24 -> 155753.45 | D13: =C13*0.3025 -> 47115.419
A14: 용 적 율 | C14: =E24/C9 -> 2.5674859 | D14: (법정 : | E14: 257.55 | F14: %)
A15: 규 모 | C15: 지상 : 27층 | D15: 지하 : 3층
A16: 구 조 | C16: RC구조
A17: 주차대수
C18: 지상 : | D18: 11 | E18: 지하 : | F18: 2015
A21: ■ 층별 면적표 | F21: ( 단위 : ㎡/평 )
A22: 구분 | C22: 아파트 | D22: 근생시설 | E22: 계 | F22: 비 고
A24: 지상층 | C24: 153042.91 | D24: 2710.54 | E24: =SUM(C24:D24) -> 155753.45 | F24: =E24/C9 -> 2.5674859
C25: =C24*0.3025 -> 46295.48 | D25: =D24*0.3025 -> 819.93835 | E25: =SUM(C25:D25) -> 47115.419
A26: 지하층 | C26: 87376.25 | D26: 583.72 | E26: =SUM(C26:D26) -> 87959.97 | F26: =E26/$C$9 -> 1.4499581
C27: =C26*0.3025 -> 26431.316 | D27: =D26*0.3025 -> 176.5753 | E27: =SUM(C27:D27) -> 26607.891 | F27: =ROUNDUP(F26/80%,0) -> 2
A28: 소 계 | C28: =C24+C26 -> 240419.16 | D28: =D24+D26 -> 3294.26 | E28: =SUM(C28:D28) -> 243713.42
C29: =C28*0.3025 -> 72726.796 | D29: =D28*0.3025 -> 996.51365 | E29: =SUM(C29:D29) -> 73723.31
A30: 비 율 | C30: =C28/$E$28 -> 0.98648306 | D30: =D28/$E$28 -> 0.013516941 | E30: =E28/$E$28 -> 1
A33: ■ 용도별 면적표
A34: 구 분 | D34: 전용면적(㎡/평) | F34: 공용면적(㎡/평) | H34: 공급면적(㎡/평) | J34: 기타공용면적(㎡/평) | L34: 계약면적(㎡/평) | N34: 비율
A35: =C22 -> 아파트 | D35: =D57+D72+D81 -> 113066.45 | E35: =D35*0.3025 -> 34202.601 | F35: =F57+F72+F81 -> 39970.05 | G35: =F35*0.3025 -> 12090.94 | H35: =D35+F35 -> 153036.5 | I35: =H35*0.3025 -> 46293.541 | J35: =C26=J57+J72+J81 -> FALSE | K35: =J35*0.3025 -> 0 | L35: =H35+J35 -> 153036.5 | M35: =L35*0.3025 -> 46293.541 | N35: =L35/$L$37 -> 0.98259652
A36: =D22 -> 근생시설 | D36: =D89 -> 2710.54 | E36: =D36*0.3025 -> 819.93835 | F36: =F89 -> 0 | G36: =F36*0.3025 -> 0 | H36: =D36+F36 -> 2710.54 | I36: =H36*0.3025 -> 819.93835 | K36: =J36*0.3025 -> 0 | L36: =H36+J36 -> 2710.54 | M36: =L36*0.3025 -> 819.93835 | N36: =L36/$L$37 -> 0.017403477
A37: 합 계 | D37: =SUM(D35:D36) -> 115776.99 | E37: =D37*0.3025 -> 35022.539 | F37: =SUM(F35:F36) -> 39970.05 | G37: =F37*0.3025 -> 12090.94 | H37: =SUM(H35:H36) -> 155747.04 | I37: =H37*0.3025 -> 47113.48 | J37: =SUM(J35:J36) -> 0 | K37: =J37*0.3025 -> 0 | L37: =SUM(L35:L36) -> 155747.04 | M37: =L37*0.3025 -> 47113.48 | N37: =L37/$L$37 -> 1
A40: ■ | B40: 일반분양 | C40: 면적표
A41: 구분 | B41: 평형 | C41: 세대수 | D41: 전용면적(m2/평) | F41: 공용면적(m2/평) | H41: 공급면적(m2/평) | J41: 기타공용면적(m2/평) | L41: 계약면적(m2/평) | N41: 비고
A42: A | B42: =E42 -> 18.09555 | C42: 142 | D42: 59.82 | E42: =D42*0.3025 -> 18.09555 | F42: 23.84 | G42: =F42*0.3025 -> 7.2116 | H42: =D42+F42 -> 83.66 | I42: =H42*0.3025 -> 25.30715 | J42: 53.36 | K42: =J42*0.3025 -> 16.1414 | L42: =H42+J42 -> 137.02 | M42: =L42*0.3025 -> 41.44855
A43: B | B43: =E43 -> 18.14395 | C43: 19 | D43: 59.98 | E43: =D43*0.3025 -> 18.14395 | F43: 23.25 | G43: =F43*0.3025 -> 7.033125 | H43: =D43+F43 -> 83.23 | I43: =H43*0.3025 -> 25.177075 | J43: 44.57 | K43: =J43*0.3025 -> 13.482425 | L43: =H43+J43 -> 127.8 | M43: =L43*0.3025 -> 38.6595
A44: C | B44: =E44 -> 18.09555 | C44: 20 | D44: 59.82 | E44: =D44*0.3025 -> 18.09555 | F44: 23.08 | G44: =F44*0.3025 -> 6.9817 | H44: =D44+F44 -> 82.9 | I44: =H44*0.3025 -> 25.07725 | J44: 44.46 | K44: =J44*0.3025 -> 13.44915 | L44: =H44+J44 -> 127.36 | M44: =L44*0.3025 -> 38.5264
A45: D | B45: =E45 -> 25.69435 | C45: 88 | D45: 84.94 | E45: =D45*0.3025 -> 25.69435 | F45: 24.49 | G45: =F45*0.3025 -> 7.408225 | H45: =D45+F45 -> 109.43 | I45: =H45*0.3025 -> 33.102575 | J45: 63.13 | K45: =J45*0.3025 -> 19.096825 | L45: =H45+J45 -> 172.56 | M45: =L45*0.3025 -> 52.1994
A46: E | B46: =E46 -> 25.6278 | C46: 70 | D46: 84.72 | E46: =D46*0.3025 -> 25.6278 | F46: 23.8 | G46: =F46*0.3025 -> 7.1995 | H46: =D46+F46 -> 108.52 | I46: =H46*0.3025 -> 32.8273 | J46: 62.97 | K46: =J46*0.3025 -> 19.048425 | L46: =H46+J46 -> 171.49 | M46: =L46*0.3025 -> 51.875725
A47: F | B47: =E47 -> 25.6641 | C47: 5 | D47: 84.84 | E47: =D47*0.3025 -> 25.6641 | F47: 41.94 | G47: =F47*0.3025 -> 12.68685 | H47: =D47+F47 -> 126.78 | I47: =H47*0.3025 -> 38.35095 | J47: 63.05 | K47: =J47*0.3025 -> 19.072625 | L47: =H47+J47 -> 189.83 | M47: =L47*0.3025 -> 57.423575
A48: G | B48: =E48 -> 25.68225 | C48: 109 | D48: 84.9 | E48: =D48*0.3025 -> 25.68225 | F48: 26.45 | G48: =F48*0.3025 -> 8.001125 | H48: =D48+F48 -> 111.35 | I48: =H48*0.3025 -> 33.683375 | J48: 63.09 | K48: =J48*0.3025 -> 19.084725 | L48: =H48+J48 -> 174.44 | M48: =L48*0.3025 -> 52.7681
A49: H | B49: =E49 -> 25.697375 | C49: 45 | D49: 84.95 | E49: =D49*0.3025 -> 25.697375 | F49: 25.64 | G49: =F49*0.3025 -> 7.7561 | H49: =D49+F49 -> 110.59 | I49: =H49*0.3025 -> 33.453475 | J49: 63.13 | K49: =J49*0.3025 -> 19.096825 | L49: =H49+J49 -> 173.72 | M49: =L49*0.3025 -> 52.5503
...

Sheet 사업검토
B2: 사 업 명 | E2: =건축개요!C5 -> 래미안목동아델리체 | M2: =TODAY() -> 45993
M3: [ 참 고 용]
B4: 위 치 | E4: =건축개요!C6 -> 서울 양천구 신정동 1326 | H4: 토지평단가 | I4: =0 -> 0 | K4: 용적률 | L4: =건축개요!C14 -> 2.5674859 | O4: 지하면/연면적 | P4: =E12/E10 -> 0.36091558 | R4: 구 분 | S4: 일반분양 분양률 | T4: 근생시설 분양률 | U4: 전체 금액
B5: 용 도 지 역 | E5: =건축개요!C7 -> 도시지역, 제2종일반주거지역 | H5: 평균개별공시지가 | I5: 0 | K5: 건폐율 | L5: =건축개요!C12 -> 0.22373376 | O5: 건축비/토지비 | P5: =M75/M70 -> #DIV/0! | R5: 착공 | S5: 0.7 | T5: 0 | U5: =$M$22*S5+$M$54*T5 -> 4.7372884e+08 | W5: 아파트 계약금 중도금 잔금 비율: (10:60:30)
B6: 토지 면적 | C6: 매입면적 | E6: =건축개요!F9 -> 60663.8 | F6: ㎡ | G6: =E6*0.3025 -> 18350.8 | H6: 자기자본 | I6: =0 -> 0 | K6: 건축규모 | L6: =건축개요!C15 -> 지상 : 27층 | M6: =건축개요!D15 -> 지하 : 3층 | O6: 상가비/전체비 | P6: =M54/M58 -> 0.037710294 | R6: D+1 | S6: 0.1 | T6: 0 | U6: =$M$22*S6+$M$54*T6 -> 67675548 | W6: 근생시설 계약금 중도금 잔금 비율: (10:40:50)
C7: 기부채납면적 | E7: =건축개요!I9 -> 0 | F7: ㎡ | G7: =E7*0.3025 -> 0 | H7: Bridge Loan | I7: =M70*110% -> 0 | K7: 세대수 | L7: =G22+G38 -> 1231 | M7: 세대/실 | O7: 실부지/전체비 | P7: =E9/E6 -> 1 | R7: D+2 | S7: 0.1 | T7: 0 | U7: =$M$22*S7+$M$54*T7 -> 67675548 | W7: 아파트 중도금 1차~6차, 10%씩 들어옴
H8: PF Tr A | I8: =M168 -> 460000000 | K8: 사업기간 | L8: =L12+8 -> 48 | O8: 수익금/투자금 | P8: =M146/I6 -> #DIV/0! | R8: D+3 | S8: 0.1 | T8: 0.5 | U8: =$M$22*S8+$M$54*T8 -> 85622759
C9: 사업면적(대지면적) | E9: =E6-E7-E8 -> 60663.8 | F9: ㎡ | G9: =E9*0.3025 -> 18350.8 | K9: 건축비 | L9: 7000 | R9: D+4 | S9: 0 | T9: 0.5 | U9: =$M$22*S9+$M$54*T9 -> 17947211 | W9: 조합분양의 경우 (10:60:20), 10은 초기자본으로 사용
B10: 연 면 적 | C10: 계 | E10: =E11+E12 -> 243713.42 | F10: ㎡ | G10: =E10*0.3025 -> 73723.31 | H10: 총 PF금액 | I10: =SUM(I7:I9) -> 460000000 | K10: 공사비 지급율 | L10: 1 | R10: 준공 | S10: 0 | T10: 0 | U10: =$M$22*S10+$M$54*T10 -> 0
C11: 지상 | E11: =건축개요!E24 -> 155753.45 | F11: ㎡ | G11: =E11*0.3025 -> 47115.419 | H11: 토지비 확보율 | I11: 1 | K11: 공사기간 | L11: =U19&"년 "&U20& "월"&" ~" -> 2026년 4월 ~ | M11: =HLOOKUP(L12,Q16:BP20,4)&"년 "&HLOOKUP(L12,Q16:BP20,5)&"월" -> 2029년 7월 | R11: 계 | S11: =SUM(S5:S10) -> 1 | T11: =SUM(T5:T10) -> 1 | U11: =SUM(U5:U10) -> 7.1264991e+08
C12: 지하 | E12: =건축개요!E26 -> 87959.97 | F12: ㎡ | G12: =E12*0.3025 -> 26607.891 | H12: PF 수수료 | I12: 0.01 | L12: 40
H13: Tr A 이자율 | I13: 0.065 | K13: 중도금무이자율 | L13: 0
K14: 중도금 간격 | L14: =ROUNDUP(L12/6,0) -> 7 | O14: 중도금 간격 | BI14: =ROUNDUP((BI16-1)/$L$14,0) -> 6 | BJ14: =ROUNDUP((BJ16-1)/$L$14,0) -> 6 | BK14: =ROUNDUP((BK16-1)/$L$14,0) -> 6 | BL14: =ROUNDUP((BL16-1)/$L$14,0) -> 7 | BM14: =ROUNDUP((BM16-1)/$L$14,0) -> 7 | BN14: =ROUNDUP((BN16-1)/$L$14,0) -> 7 | BO14: =ROUNDUP((BO16-1)/$L$14,0) -> 7 | BP14: =ROUNDUP((BP16-1)/$L$14,0) -> 7
H15: 부가세 비율 | I15: 0.1 | K15: 일반분양 평균분양가 | L15: 42765 | O15: 중도금 입금월 | BI15: =IF(BH14=BI14,"",BI14) -> 6 | BJ15: =IF(BI14=BJ14,"",BJ14) | BK15: =IF(BJ14=BK14,"",BK14) | BL15: =IF(BK14=BL14,"",BL14) -> 7 | BM15: =IF(BL14=BM14,"",BM14) | BN15: =IF(BM14=BN14,"",BN14) | BO15: =IF(BN14=BO14,"",BO14) | BP15: =IF(BO14=BP14,"",BP14)
O16: 공사기간 | U16: 1 | V16: =U16+1 -> 2 | W16: =V16+1 -> 3 | X16: =W16+1 -> 4 | Y16: =X16+1 -> 5 | Z16: =Y16+1 -> 6 | AA16: =Z16+1 -> 7 | AB16: =AA16+1 -> 8 | AC16: =AB16+1 -> 9 | ... BP16: =BO16+1 -> 48
O17: 공정율 | P17: 0 | Q17: 0 | R17: 0 | S17: 0 | U17: =2.5% -> 0.025 | V17: 0.025 | W17: 0.025 | X17: 0.025 | Y17: 0.025 | Z17: 0.025 | AA17: 0.025 | AB17: 0.025 | AC17: 0.025 | AD17: 0.025 | AE17: 0.025 | AF17: 0.025 | AG17: 0.025 | AH17: 0.025 | AI17: 0.025 | AJ17: 0.025 | AK17: 0.025 | AL17: 0.025 | AM17: 0.025 | AN17: 0.025 | AO17: 0.025 | AP17: 0.025 | AQ17: 0.025 | AR17: 0.025 | AS17: 0.025 | AT17: 0.025 | AU17: 0.025 | AV17: 0.025 | AW17: 0.025 | AX17: 0.025 | AY17: 0.025 | AZ17: 0.025 | BA17: 0.025 | BB17: 0.025 | BC17: 0.025 | BD17: 0.025 | BE17: 0.025 | BF17: 0.025 | BG17: 0.025 | BH17: 0.025
O18: 누적공정율 | U18: =T18+U17 -> 0.025 | V18: =U18+V17 -> 0.05 | W18: =V18+W17 -> 0.075 | X18: =W18+X17 -> 0.1 | Y18: =X18+Y17 -> 0.125 | Z18: =Y18+Z17 -> 0.15 | AA18: =Z18+AA17 -> 0.175 | AB18: =AA18+AB17 -> 0.2 | ... BH18: =BG18+BH17 -> 1
M19: (단위 : 천원) | O19: 년 도 | P19: 2025 | Q19: =IF(Q20=1,(P19+1),P19) -> 2025 | R19: =IF(R20=1,(Q19+1),Q19) -> 2026 | S19: =IF(S20=1,(R19+1),R19) -> 2026 | T19: =IF(T20=1,(S19+1),S19) -> 2026 | U19: =IF(U20=1,(T19+1),T19) -> 2026 | V19: =IF(V20=1,(U19+1),U19) -> 2026 | W19: =IF(W20=1,(V19+1),V19) -> 2026 | X19: =IF(X20=1,(W19+1),W19) -> 2026 | ... BP19: =IF(BP20=1,(BO19+1),BO19) -> 2030
B20: 구 분 | G20: 내 역 | L20: 비율 | M20: 금 액 | P20: 11 | Q20: =MOD((P20),12)+1 -> 12 | R20: =MOD((Q20),12)+1 -> 1 | S20: =MOD((R20),12)+1 -> 2 | T20: =MOD((S20),12)+1 -> 3 | U20: =MOD((T20),12)+1 -> 4 | V20: =MOD((U20),12)+1 -> 5 | W20: =MOD((V20),12)+1 -> 6 | X20: =MOD((W20),12)+1 -> 7 | ... BP20: =MOD((BO20),12)+1 -> 3 | BQ20: 계 | BR20: 검 산 | BS20: 오차
L21: (%) | P21: 계약 | S21: PF | T21: 허가 | U21: 착공 | V21: d+1 | W21: d+2 | X21: d+3 | Y21: d+4 | AB21: 중도금 1차 | AH21: 중도금 2차 | AN21: 중도금 3차 | AT21: 중도금 4차 | AZ21: 중도금 5차 | BF21: 중도금 6차 | BH21: 준공 | BI21: 입주 | BJ21: 정산
B22: 매 출 | C22: 일반분양 | D22: 소 계 | E22: =SUMPRODUCT(E23:E37,G23:G37) -> 15824.985 | G22: =SUM(G23:G37) -> 644 | H22: 부가세 별도 | I22: 부가세 포함 | L22: =M22/M$69 -> 0.72179116 | M22: =SUM(M23:M37) -> 6.7675548e+08 | O22: =C22 -> 일반분양 | P22: =SUM(P23:P37) -> 0 | Q22: =SUM(Q23:Q37) -> 0 | R22: =SUM(R23:R37) -> 0 | S22: =SUM(S23:S37) -> 0 | T22: =SUM(T23:T37) -> 0 | U22: =SUM(U23:U37) -> 0 | V22: =SUM(V23:V37) -> 47372884 | W22: =SUM(W23:W37) -> 6767554.8 | ... BP22: =SUM(BP23:BP37) -> 0 | BQ22: =SUM(P22:BP22) -> 6.7675548e+08 | BR22: =+M22 -> 6.7675548e+08 | BS22: =BQ22-BR22 -> 0
D23: A | E23: =건축개요!B42 -> 18.09555 | F23: 평형 | G23: =건축개요!C42 -> 142 | H23: =IF(건축개요!D42>85,I23*(1-$I$15),I23) -> 42765 | I23: =L15 -> 42765 | J23: = 세대당 가격 | K23: =E23*I23 -> 773856.2 | L23: =M23/M$69 -> 0.11720021 | M23: =E23*G23*I23 -> 1.0988758e+08 | V23: =$M23*$S$5*10% -> 7692130.6 | W23: =$M23*$S$6*10% -> 1098875.8 | X23: =$M23*$S$7*10% -> 1098875.8 | Y23: =$M23*$S$8*10% -> 1098875.8 | AB23: =$M23*10% -> 10988758 | AH23: =$M23*10% -> 10988758 | AN23: =$M23*10% -> 10988758 | AT23: =$M23*10% -> 10988758 | AZ23: =$M23*10% -> 10988758 | BF23: =$M23*10% -> 10988758 | BI23: =$M23*30% -> 32966274 | BQ23: =SUM(P23:BP23) -> 1.0988758e+08 | BR23: =$M23 -> 1.0988758e+08 | BS23: =BQ23-BR23 -> 0
D24: B | E24: =건축개요!B43 -> 18.14395 | F24: 평형 | G24: =건축개요!C43 -> 19 | H24: =IF(건축개요!D43>85,I24*(1-$I$15),I24) -> 42765 | I24: =$I$23 -> 42765 | J24: = 세대당 가격 | K24: =E24*I24 -> 775926.02 | L24: =M24/M$69 -> 0.015723662 | M24: =E24*G24*I24 -> 14742594 | V24: =$M24*$S$5*10% -> 1031981.6 | W24: =$M24*$S$6*10% -> 147425.94 | X24: =$M24*$S$7*10% -> 147425.94 | Y24: =$M24*$S$8*10% -> 147425.94 | AB24: =$M24*10% -> 1474259.4 | AH24: =$M24*10% -> 1474259.4 | AN24: =$M24*10% -> 1474259.4 | AT24: =$M24*10% -> 1474259.4 | AZ24: =$M24*10% -> 1474259.4 | BF24: =$M24*10% -> 1474259.4 | BI24: =$M24*30% -> 4422778.3 | BQ24: =SUM(P24:BP24) -> 14742594 | BR24: =$M24 -> 14742594 | BS24: =BQ24-BR24 -> 0
D25: C | E25: =건축개요!B44 -> 18.09555 | F25: 평형 | G25: =건축개요!C44 -> 20 | H25: =IF(건축개요!D44>85,I25*(1-$I$15),I25) -> 42765 | I25: =$I$23 -> 42765 | J25: = 세대당 가격 | K25: =E25*I25 -> 773856.2 | L25: =M25/M$69 -> 0.016507072 | M25: =E25*G25*I25 -> 15477124 | V25: =$M25*$S$5*10% -> 1083398.7 | W25: =$M25*$S$6*10% -> 154771.24 | X25: =$M25*$S$7*10% -> 154771.24 | Y25: =$M25*$S$8*10% -> 154771.24 | AB25: =$M25*10% -> 1547712.4 | AH25: =$M25*10% -> 1547712.4 | AN25: =$M25*10% -> 1547712.4 | AT25: =$M25*10% -> 1547712.4 | AZ25: =$M25*10% -> 1547712.4 | BF25: =$M25*10% -> 1547712.4 | BI25: =$M25*30% -> 4643137.2 | BQ25: =SUM(P25:BP25) -> 15477124 | BR25: =$M25 -> 15477124 | BS25: =BQ25-BR25 -> 0
D26: D | E26: =건축개요!B45 -> 25.69435 | F26: 평형 | G26: =건축개요!C45 -> 88 | H26: =IF(건축개요!D45>85,I26*(1-$I$15),I26) -> 42765 | I26: =$I$23 -> 42765 | J26: = 세대당 가격 | K26: =E26*I26 -> 1098818.9 | L26: =M26/M$69 -> 0.10313084 | M26: =E26*G26*I26 -> 96696061 | V26: =$M26*$S$5*10% -> 6768724.3 | W26: =$M26*$S$6*10% -> 966960.61 | X26: =$M26*$S$7*10% -> 966960.61 | Y26: =$M26*$S$8*10% -> 966960.61 | AB26: =$M26*10% -> 9669606.1 | AH26: =$M26*10% -> 9669606.1 | AN26: =$M26*10% -> 9669606.1 | AT26: =$M26*10% -> 9669606.1 | AZ26: =$M26*10% -> 9669606.1 | BF26: =$M26*10% -> 9669606.1 | BI26: =$M26*30% -> 29008818 | BQ26: =SUM(P26:BP26) -> 96696061 | BR26: =$M26 -> 96696061 | BS26: =BQ26-BR26 -> 0
D27: E | E27: =건축개요!B46 -> 25.6278 | F27: 평형 | G27: =건축개요!C46 -> 70 | H27: =IF(건축개요!D46>85,I27*(1-$I$15),I27) -> 42765 | I27: =$I$23 -> 42765 | J27: = 세대당 가격 | K27: =E27*I27 -> 1095972.9 | L27: =M27/M$69 -> 0.081823418 | M27: =E27*G27*I27 -> 76718101 | V27: =$M27*$S$5*10% -> 5370267 | W27: =$M27*$S$6*10% -> 767181.01 | X27: =$M27*$S$7*10% -> 767181.01 | Y27: =$M27*$S$8*10% -> 767181.01 | AB27: =$M27*10% -> 7671810.1 | AH27: =$M27*10% -> 7671810.1 | AN27: =$M27*10% -> 7671810.1 | AT27: =$M27*10% -> 7671810.1 | AZ27: =$M27*10% -> 7671810.1 | BF27: =$M27*10% -> 7671810.1 | BI27: =$M27*30% -> 23015430 | BQ27: =SUM(P27:BP27) -> 76718101 | BR27: =$M27 -> 76718101 | BS27: =BQ27-BR27 -> 0
D28: F | E28: =건축개요!B47 -> 25.6641 | F28: 평형 | G28: =건축개요!C47 -> 5 | H28: =IF(건축개요!D47>85,I28*(1-$I$15),I28) -> 42765 | I28: =$I$23 -> 42765 | J28: = 세대당 가격 | K28: =E28*I28 -> 1097525.2 | L28: =M28/M$69 -> 0.0058528083 | M28: =E28*G28*I28 -> 5487626.2 | V28: =$M28*$S$5*10% -> 384133.83 | W28: =$M28*$S$6*10% -> 54876.262 | X28: =$M28*$S$7*10% -> 54876.262 | Y28: =$M28*$S$8*10% -> 54876.262 | AB28: =$M28*10% -> 548762.62 | AH28: =$M28*10% -> 548762.62 | AN28: =$M28*10% -> 548762.62 | AT28: =$M28*10% -> 548762.62 | AZ28: =$M28*10% -> 548762.62 | BF28: =$M28*10% -> 548762.62 | BI28: =$M28*30% -> 1646287.9 | BQ28: =SUM(P28:BP28) -> 5487626.2 | BR28: =$M28 -> 5487626.2 | BS28: =BQ28-BR28 -> 0
D29: G | E29: =건축개요!B48 -> 25.68225 | F29: 평형 | G29: =건축개요!C48 -> 109 | H29: =IF(건축개요!D48>85,I29*(1-$I$15),I29) -> 42765 | I29: =$I$23 -> 42765 | J29: = 세대당 가격 | K29: =E29*I29 -> 1098301.4 | L29: =M29/M$69 -> 0.12768145 | M29: =E29*G29*I29 -> 1.1971485e+08 | V29: =$M29*$S$5*10% -> 8380039.8 | W29: =$M29*$S$6*10% -> 1197148.5 | X29: =$M29*$S$7*10% -> 1197148.5 | Y29: =$M29*$S$8*10% -> 1197148.5 | AB29: =$M29*10% -> 11971485 | AH29: =$M29*10% -> 11971485 | AN29: =$M29*10% -> 11971485 | AT29: =$M29*10% -> 11971485 | AZ29: =$M29*10% -> 11971485 | BF29: =$M29*10% -> 11971485 | BI29: =$M29*30% -> 35914456 | BQ29: =SUM(P29:BP29) -> 1.1971485e+08 | BR29: =$M29 -> 1.1971485e+08 | BS29: =BQ29-BR29 -> 0
D30: H | E30: =건축개요!B49 -> 25.697375 | F30: 평형 | G30: =건축개요!C49 -> 45 | H30: =IF(건축개요!D49>85,I30*(1-$I$15),I30) -> 42765 | I30: =$I$23 -> 42765 | J30: = 세대당 가격 | K30: =E30*I30 -> 1098948.2 | L30: =M30/M$69 -> 0.052743571 | M30: =E30*G30*I30 -> 49452671 | V30: =$M30*$S$5*10% -> 3461687 | W30: =$M30*$S$6*10% -> 494526.71 | X30: =$M30*$S$7*10% -> 494526.71 | Y30: =$M30*$S$8*10% -> 494526.71 | AB30: =$M30*10% -> 4945267.1 | AH30: =$M30*10% -> 4945267.1 | AN30: =$M30*10% -> 4945267.1 | AT30: =$M30*10% -> 4945267.1 | AZ30: =$M30*10% -> 4945267.1 | BF30: =$M30*10% -> 4945267.1 | BI30: =$M30*30% -> 14835801 | BQ30: =SUM(P30:BP30) -> 49452671 | BR30: =$M30 -> 49452671 | BS30: =BQ30-BR30 -> 0
D31: I | E31: =건축개요!B50 -> 25.58545 | F31: 평형 | G31: =건축개요!C50 -> 75 | H31: =IF(건축개요!D50>85,I31*(1-$I$15),I31) -> 42765 | I31: =$I$23 -> 42765 | J31: = 세대당 가격 | K31: =E31*I31 -> 1094161.8 | L31: =M31/M$69 -> 0.087523077 | M31: =E31*G31*I31 -> 82062133 | V31: =$M31*$S$5*10% -> 5744349.3 | W31: =$M31*$S$6*10% -> 820621.33 | X31: =$M31*$S$7*10% -> 820621.33 | Y31: =$M31*$S$8*10% -> 820621.33 | AB31: =$M31*10% -> 8206213.3 | AH31: =$M31*10% -> 8206213.3 | AN31: =$M31*10% -> 8206213.3 | AT31: =$M31*10% -> 8206213.3 | AZ31: =$M31*10% -> 8206213.3 | BF31: =$M31*10% -> 8206213.3 | BI31: =$M31*30% -> 24618640 | BQ31: =SUM(P31:BP31) -> 82062133 | BR31: =$M31 -> 82062133 | BS31: =BQ31-BR31 -> 0
D32: J | E32: =건축개요!B51 -> 35.080925 | F32: 평형 | G32: =건축개요!C51 -> 71 | H32: =IF(건축개요!D51>85,I32*(1-$I$15),I32) -> 38488.5 | I32: =$I$23 -> 42765 | J32: = 세대당 가격 | K32: =E32*I32 -> 1500235.8 | L32: =M32/M$69 -> 0.11360505 | M32: =E32*G32*I32 -> 1.0651674e+08 | V32: =$M32*$S$5*10% -> 7456171.7 | W32: =$M32*$S$6*10% -> 1065167.4 | X32: =$M32*$S$7*10% -> 1065167.4 | Y32: =$M32*$S$8*10% -> 1065167.4 | AB32: =$M32*10% -> 10651674 | AH32: =$M32*10% -> 10651674 | AN32: =$M32*10% -> 10651674 | AT32: =$M32*10% -> 10651674 | AZ32: =$M32*10% -> 10651674 | BF32: =$M32*10% -> 10651674 | BI32: =$M32*30% -> 31955022 | BQ32: =SUM(P32:BP32) -> 1.0651674e+08 | BR32: =$M32 -> 1.0651674e+08 | BS32: =BQ32-BR32 -> 0
D33: K | E33: =건축개요!B52 -> 0 | F33: 평형 | G33: =건축개요!C52 -> 0 | H33: =IF(건축개요!D52>85,I33*(1-$I$15),I33) -> 42765 | I33: =$I$23 -> 42765 | J33: = 세대당 가격 | K33: =E33*I33 -> 0 | L33: =M33/M$69 -> 0 | M33: =E33*G33*I33 -> 0 | V33: =$M33*$S$5*10% -> 0 | W33: =$M33*$S$6*10% -> 0 | X33: =$M33*$S$7*10% -> 0 | Y33: =$M33*$S$8*10% -> 0 | AB33: =$M33*10% -> 0 | AH33: =$M33*10% -> 0 | AN33: =$M33*10% -> 0 | AT33: =$M33*10% -> 0 | AZ33: =$M33*10% -> 0 | BF33: =$M33*10% -> 0 | BI33: =$M33*30% -> 0 | BQ33: =SUM(P33:BP33) -> 0 | BR33: =$M33 -> 0 | BS33: =BQ33-BR33 -> 0
D34: L | E34: =건축개요!B53 -> 0 | F34: 평형 | G34: =건축개요!C53 -> 0 | H34: =IF(건축개요!D53>85,I34*(1-$I$15),I34) -> 42765 | I34: =$I$23 -> 42765 | J34: = 세대당 가격 | K34: =E34*I34 -> 0 | L34: =M34/M$69 -> 0 | M34: =E34*G34*I34 -> 0 | V34: =$M34*$S$5*10% -> 0 | W34: =$M34*$S$6*10% -> 0 | X34: =$M34*$S$7*10% -> 0 | Y34: =$M34*$S$8*10% -> 0 | AB34: =$M34*10% -> 0 | AH34: =$M34*10% -> 0 | AN34: =$M34*10% -> 0 | AT34: =$M34*10% -> 0 | AZ34: =$M34*10% -> 0 | BF34: =$M34*10% -> 0 | BI34: =$M34*30% -> 0 | BQ34: =SUM(P34:BP34) -> 0 | BR34: =$M34 -> 0 | BS34: =BQ34-BR34 -> 0
D35: M | E35: =건축개요!B54 -> 0 | F35: 평형 | G35: =건축개요!C54 -> 0 | H35: =IF(건축개요!D54>85,I35*(1-$I$15),I35) -> 42765 | I35: =$I$23 -> 42765 | J35: = 세대당 가격 | K35: =E35*I35 -> 0 | L35: =M35/M$69 -> 0 | M35: =E35*G35*I35 -> 0 | V35: =$M35*$S$5*10% -> 0 | W35: =$M35*$S$6*10% -> 0 | X35: =$M35*$S$7*10% -> 0 | Y35: =$M35*$S$8*10% -> 0 | AB35: =$M35*10% -> 0 | AH35: =$M35*10% -> 0 | AN35: =$M35*10% -> 0 | AT35: =$M35*10% -> 0 | AZ35: =$M35*10% -> 0 | BF35: =$M35*10% -> 0 | BI35: =$M35*30% -> 0 | BQ35: =SUM(P35:BP35) -> 0 | BR35: =$M35 -> 0 | BS35: =BQ35-BR35 -> 0
... D37: O | E37: =건축개요!B56 -> 0 | F37: 평형 | G37: =건축개요!C56 -> 0 | H37: =IF(건축개요!D56>85,I37*(1-$I$15),I37) -> 42765 | I37: =$I$23 -> 42765 | J37: = 세대당 가격 | K37: =E37*I37 -> 0 | L37: =M37/M$69 -> 0 | M37: =E37*G37*I37 -> 0 | V37: =$M37*$S$5*10% -> 0 | W37: =$M37*$S$6*10% -> 0 | X37: =$M37*$S$7*10% -> 0 | Y37: =$M37*$S$8*10% -> 0 | AB37: =$M37*10% -> 0 | AH37: =$M37*10% -> 0 | AN37: =$M37*10% -> 0 | AT37: =$M37*10% -> 0 | AZ37: =$M37*10% -> 0 | BF37: =$M37*10% -> 0 | BI37: =$M37*30% -> 0 | BQ37: =SUM(P37:BP37) -> 0 | BR37: =$M37 -> 0 | BS37: =BQ37-BR37 -> 0
D38: 소 계 | E38: =SUMPRODUCT(E39:E48,G39:G48) -> 14551.433 | G38: =SUM(G39:G48) -> 587 | K38: 시세가의 80% 가정 | L38: =M38/M$69 -> 0.22495094 | M38: =SUM(M39:M48) -> 2.1091527e+08 | O38: 조합분양 | P38: =SUM(P39:P48) -> 21091527 | Q38: =SUM(Q39:Q48) -> 0 | R38: =SUM(R39:R48) -> 0 | S38: =SUM(S39:S48) -> 0 | T38: =SUM(T39:T48) -> 0 | U38: =SUM(U39:U48) -> 0 | V38: =SUM(V39:V48) -> 21091527 | W38: =SUM(W39:W48) -> 0 | ... BP38: =SUM(BP39:BP48) -> 0 | BQ38: =SUM(P38:BP38) -> 2.1091527e+08 | BR38: =+M38 -> 2.1091527e+08 | BS38: =BQ38-BR38 -> 0
C39: 조합분양 | D39: A | E39: =건축개요!B62 -> 18.09555 | F39: 평형 | G39: =건축개요!C62 -> 8 | J39: = 세대당 가격 | K39: =E39*$L$15*0.8 -> 619084.96 | L39: =M39/M$69 -> 0.011948182 | M39: =E39*K39 -> 11202683 | P39: =$M39*10% -> 1120268.3 | V39: =$M39*10% -> 1120268.3 | AB39: =$M39*10% -> 1120268.3 | AH39: =$M39*10% -> 1120268.3 | AN39: =$M39*10% -> 1120268.3 | AT39: =$M39*10% -> 1120268.3 | AZ39: =$M39*10% -> 1120268.3 | BF39: =$M39*10% -> 1120268.3 | BI39: =$M39*20% -> 2240536.6 | BQ39: =SUM(P39:BP39) -> 11202683 | BR39: =$M39 -> 11202683 | BS39: =BQ39-BR39 -> 0
D40: B | E40: =건축개요!B63 -> 18.14395 | F40: 평형 | G40: =건축개요!C63 -> 8 | J40: = 세대당 가격 | K40: =E40*$L$15*0.8 -> 620740.82 | L40: =M40/M$69 -> 0.012012182 | M40: =E40*K40 -> 11262690 | P40: =$M40*10% -> 1126269 | V40: =$M40*10% -> 1126269 | AB40: =$M40*10% -> 1126269 | AH40: =$M40*10% -> 1126269 | AN40: =$M40*10% -> 1126269 | AT40: =$M40*10% -> 1126269 | AZ40: =$M40*10% -> 1126269 | BF40: =$M40*10% -> 1126269 | BI40: =$M40*20% -> 2252538.1 | BQ40: =SUM(P40:BP40) -> 11262690 | BR40: =$M40 -> 11262690 | BS40: =BQ40-BR40 -> 0
D41: C | E41: =건축개요!B64 -> 18.09555 | F41: 평형 | G41: =건축개요!C64 -> 87 | J41: = 세대당 가격 | K41: =E41*$L$15*0.8 -> 619084.96 | L41: =M41/M$69 -> 0.011948182 | M41: =E41*K41 -> 11202683 | P41: =$M41*10% -> 1120268.3 | V41: =$M41*10% -> 1120268.3 | AB41: =$M41*10% -> 1120268.3 | AH41: =$M41*10% -> 1120268.3 | AN41: =$M41*10% -> 1120268.3 | AT41: =$M41*10% -> 1120268.3 | AZ41: =$M41*10% -> 1120268.3 | BF41: =$M41*10% -> 1120268.3 | BI41: =$M41*20% -> 2240536.6 | BQ41: =SUM(P41:BP41) -> 11202683 | BR41: =$M41 -> 11202683 | BS41: =BQ41-BR41 -> 0
D42: D | E42: =건축개요!B65 -> 25.69435 | F42: 평형 | G42: =건축개요!C65 -> 108 | J42: = 세대당 가격 | K42: =E42*$L$15*0.8 -> 879055.1 | L42: =M42/M$69 -> 0.024089818 | M42: =E42*K42 -> 22586749 | P42: =$M42*10% -> 2258674.9 | V42: =$M42*10% -> 2258674.9 | AB42: =$M42*10% -> 2258674.9 | AH42: =$M42*10% -> 2258674.9 | AN42: =$M42*10% -> 2258674.9 | AT42: =$M42*10% -> 2258674.9 | AZ42: =$M42*10% -> 2258674.9 | BF42: =$M42*10% -> 2258674.9 | BI42: =$M42*20% -> 4517349.9 | BQ42: =SUM(P42:BP42) -> 22586749 | BR42: =$M42 -> 22586749 | BS42: =BQ42-BR42 -> 0
...

Sheet 개발-운영
B2: =사업검토!B2 -> 사 업 명 | I2: 작성일자 : | J2: =사업검토!L14 -> 7
I3: 출력일자 : | J3: =+TODAY() -> 45993
B4: ■ CASH-FLOW
Q5: (단위 : 평, 천원)
B6: 구 분 | E6: 계 | F6: Y+0 | G6: 1 | H6: =G6+1 -> 2 | I6: =H6+1 -> 3 | J6: =I6+1 -> 4 | K6: =J6+1 -> 5 | L6: =K6+1 -> 6 | M6: =L6+1 -> 7 | N6: =M6+1 -> 8 | O6: =N6+1 -> 9 | Q6: 비 고
F7: 개 발
F8: 39661 | G8: =F8+31 -> 39692 | H8: =G8+365.25 -> 40057.25 | I8: =H8+365.25 -> 40422.5 | J8: =I8+365.25 -> 40787.75 | K8: =J8+365.25 -> 41153 | L8: =K8+365.25 -> 41518.25 | M8: =L8+365.25 -> 41883.5 | N8: =M8+365.25 -> 42248.75 | O8: =N8+365.25 -> 42614
G9: =G8+364 -> 40056 | H9: =H8+364 -> 40421.25 | I9: =I8+364 -> 40786.5 | J9: =J8+364 -> 41151.75 | K9: =K8+364 -> 41517 | L9: =L8+364 -> 41882.25 | M9: =M8+364 -> 42247.5 | N9: =N8+364 -> 42612.75 | O9: =O8+364 -> 42978
B10: 매출 (A) | C10: =사업검토!#REF! -> #REF! | E10: =SUM(F10:M10) -> #REF! | F10: =SUM(사업검토!#REF!) -> #REF! | G10: =SUM(사업검토!#REF!) -> #REF! | H10: =SUM(사업검토!#REF!) -> #REF! | I10: =SUM(사업검토!#REF!) -> #REF! | J10: =SUM(사업검토!#REF!) -> #REF!
C11: =사업검토!#REF! -> #REF! | E11: =SUM(F11:M11) -> #REF! | F11: =SUM(사업검토!#REF!) -> #REF! | G11: =SUM(사업검토!#REF!) -> #REF! | H11: =SUM(사업검토!#REF!) -> #REF! | I11: =SUM(사업검토!#REF!) -> #REF! | J11: =SUM(사업검토!#REF!) -> #REF!
C12: =사업검토!C22 -> 일반분양 | E12: =SUM(F12:M12) -> #REF! | F12: =SUM(사업검토!AD22) -> 0 | G12: =SUM(사업검토!AE22:AR22) -> 1.353511e+08 | H12: =SUM(사업검토!AS22:BD22) -> 1.353511e+08 | I12: =SUM(사업검토!BE22:BP22) -> 2.7070219e+08 | J12: =SUM(사업검토!#REF!) -> #REF!
C13: =사업검토!C54 -> 근생시설 | E13: =SUM(F13:M13) -> #REF! | F13: =SUM(사업검토!AD54) -> 0 | G13: =SUM(사업검토!AE54:AR54) -> 7178884.3 | H13: =SUM(사업검토!AS54:BD54) -> 7178884.3 | I13: =SUM(사업검토!BE54:BP54) -> 17947211 | J13: =SUM(사업검토!#REF!) -> #REF!
C14: =사업검토!#REF! -> #REF! | E14: =SUM(F14:M14) -> #REF! | F14: =SUM(사업검토!#REF!) -> #REF! | G14: =SUM(사업검토!#REF!) -> #REF! | H14: =SUM(사업검토!#REF!) -> #REF! | I14: =SUM(사업검토!#REF!) -> #REF! | J14: =SUM(사업검토!#REF!) -> #REF!
C15: =사업검토!#REF! -> #REF! | E15: =SUM(F15:M15) -> #REF! | F15: =SUM(사업검토!#REF!) -> #REF! | G15: =SUM(사업검토!#REF!) -> #REF! | H15: =SUM(사업검토!#REF!) -> #REF! | I15: =SUM(사업검토!#REF!) -> #REF! | J15: =SUM(사업검토!#REF!) -> #REF!
C16: 소 계 | E16: =SUM(F16:M16) -> #REF! | F16: =SUM(사업검토!AD58) -> 0 | G16: =SUM(사업검토!AE58:AR58) -> 1.8471304e+08 | H16: =SUM(사업검토!AS58:BD58) -> 1.8471304e+08 | I16: =SUM(사업검토!BE58:BP58) -> 3.6606479e+08 | J16: =SUM(사업검토!#REF!) -> #REF!
B17: 부가가치세 (B) | E17: =SUM(F17:M17) -> #REF! | F17: =SUM(사업검토!AD59) -> 0 | G17: =SUM(사업검토!AE59:AR59) -> 2848223.2 | H17: =SUM(사업검토!AS59:BD59) -> 2848223.2 | I17: =SUM(사업검토!BE59:BP59) -> 6055390.6 | J17: =SUM(사업검토!#REF!) -> #REF!
B18: 기타 수입 (C) | E18: =SUM(F18:M18) -> 0 | F18: 0 | G18: 0 | H18: 0 | I18: 0 | J18: 0
B19: 총 계 (A-B+C) | E19: =SUM(F19:M19) -> #REF! | F19: =F16-F17+F18 -> 0 | G19: =G16-G17+G18 -> 1.8186481e+08 | H19: =H16-H17+H18 -> 1.8186481e+08 | I19: =I16-I17+I18 -> 3.600094e+08 | J19: =J16-J17+J18 -> #REF!
B20: 개발 원가 | C20: 토지비 | E20: =SUM(F20:M20) -> #REF! | F20: =-SUM(사업검토!AD74) -> 0 | G20: =-SUM(사업검토!AE74:AR74) -> 0 | H20: =-SUM(사업검토!AS74:BD74) -> 0 | I20: =-SUM(사업검토!BE74:BP74) -> 0 | J20: =-SUM(사업검토!#REF!) -> #REF! | Q20: 취등록세, 등기수수료 등 포함
C21: 공사비 | E21: =SUM(F21:M21) -> #REF! | F21: =-SUM(사업검토!AD81) -> -2211699.3 | G21: =-SUM(사업검토!AE81:AR81) -> -1.9845588e+08 | H21: =-SUM(사업검토!AS81:BD81) -> -1.96104e+08 | I21: =-SUM(사업검토!BE81:BP81) -> -77689831 | J21: =-SUM(사업검토!#REF!) -> #REF!
C22: 용역비 | E22: =SUM(F22:M22) -> #REF! | F22: =-SUM(사업검토!AD90) -> -421492.2 | G22: =-SUM(사업검토!AE90:AR90) -> -8492689.7 | H22: =-SUM(사업검토!AS90:BD90) -> -7649705.2 | I22: =-SUM(사업검토!BE90:BP90) -> -3884374.9 | J22: =-SUM(사업검토!#REF!) -> #REF!
C23: 판매비 | E23: =SUM(F23:M23) -> #REF! | F23: =-SUM(사업검토!AD107) -> -170000 | G23: =-SUM(사업검토!AE107:AR107) -> -600733.06 | H23: =-SUM(사업검토!AS107:BD107) -> -430733.06 | I23: =-SUM(사업검토!BE107:BP107) -> -1076832.7 | J23: =-SUM(사업검토!#REF!) -> #REF!
C24: 간접경비 및 이자 | E24: =SUM(F24:M24) -> #REF! | F24: =-SUM(사업검토!AD125) -> -532730.49 | G24: =-SUM(사업검토!AE125:AR125) -> -7458226.9 | H24: =-SUM(사업검토!AS125:BD125) -> -25880837 | I24: =-SUM(사업검토!BE125:BP125) -> -3196382.9 | J24: =-SUM(사업검토!#REF!) -> #REF!
C25: 예비비 | E25: =SUM(F25:N25) -> #REF! | F25: =-SUM(사업검토!AD126) -> 0 | G25: =-SUM(사업검토!AE126:AR126) -> -10000000 | H25: =-SUM(사업검토!AS126:BD126) -> 0 | I25: =-SUM(사업검토!BE126:BP126) -> 0 | J25: =-SUM(사업검토!#REF!) -> #REF!
C26: 소 계 | E26: =SUM(F26:N26) -> #REF! | F26: =-SUM(사업검토!AD153) -> -3335922 | G26: =-SUM(사업검토!AE153:AR153) -> -2.2500753e+08 | H26: =-SUM(사업검토!AS153:BD153) -> -2.3006528e+08 | I26: =-SUM(사업검토!BE153:BP153) -> -85847422 | J26: =-SUM(사업검토!#REF!) -> #REF!
C27: 금융비용 | E27: =SUM(F27:N27) -> #REF! | F27: =SUM(사업검토!AD142) -> 1969567.4 | G27: =SUM(사업검토!AE142:AR142) -> 23607291 | H27: =SUM(사업검토!AS142:BD142) -> 13757550 | I27: =SUM(사업검토!BE142:BP142) -> 3181786.6 | J27: =-SUM(사업검토!#REF!) -> #REF!
C28: 일반관리비 | E28: =SUM(F28:N28) -> #REF! | F28: =-SUM(사업검토!#REF!) -> #REF! | G28: =-SUM(사업검토!#REF!) -> #REF! | H28: =-SUM(사업검토!#REF!) -> #REF! | I28: =-SUM(사업검토!#REF!) -> #REF! | J28: =-SUM(사업검토!#REF!) -> #REF!
C29: 총 계 | E29: =E26+E27+E28 -> #REF! | F29: =F26+F27+F28 -> #REF! | G29: =G26+G27+G28 -> #REF! | H29: =H26+H27+H28 -> #REF! | I29: =I26+I27+I28 -> #REF! | J29: =J26+J27+J28 -> #REF!
B30: Loan | C30: 대출 | D30: 토지비 | E30: =SUM(F30:N30) -> #REF! | F30: =SUM(사업검토!#REF!) -> #REF! | G30: =SUM(사업검토!#REF!) -> #REF! | H30: =SUM(사업검토!#REF!) -> #REF! | I30: =SUM(사업검토!#REF!) -> #REF! | J30: =SUM(사업검토!#REF!) -> #REF! | Q30: 토지비 대출
D31: 사업비 | E31: =SUM(F31:N31) -> #REF! | F31: =SUM(사업검토!#REF!) -> #REF! | G31: =SUM(사업검토!#REF!) -> #REF! | H31: =SUM(사업검토!#REF!) -> #REF! | I31: =SUM(사업검토!#REF!) -> #REF! | J31: =SUM(사업검토!#REF!) -> #REF! | Q31: 공사비 및 기타 사업비 대출
D32: 소 계 | E32: =SUM(F32:N32) -> #REF! | F32: =F30+F31 -> #REF! | G32: =G30+G31 -> #REF! | H32: =H30+H31 -> #REF! | I32: =I30+I31 -> #REF! | J32: =J30+J31 -> #REF!
C33: 이자 대출 | D33: 토지비 이자 | E33: =SUM(F33:N33) -> #REF! | F33: =SUM(사업검토!#REF!) -> #REF! | G33: =SUM(사업검토!#REF!) -> #REF! | H33: =SUM(사업검토!#REF!) -> #REF! | I33: =SUM(사업검토!#REF!) -> #REF! | J33: =SUM(사업검토!#REF!) -> #REF!
D34: 사업비 이자 | E34: =SUM(F34:N34) -> #REF! | F34: =SUM(사업검토!#REF!) -> #REF! | G34: =SUM(사업검토!#REF!) -> #REF! | H34: =SUM(사업검토!#REF!) -> #REF! | I34: =SUM(사업검토!#REF!) -> #REF! | J34: =SUM(사업검토!#REF!) -> #REF!
D35: 소 계 | E35: =SUM(F35:N35) -> #REF! | F35: =F33+F34 -> #REF! | G35: =G33+G34 -> #REF! | H35: =H33+H34 -> #REF! | I35: =I33+I34 -> #REF! | J35: =J33+J34 -> #REF!
C36: 상환 | E36: =SUM(F36:N36) -> #REF! | F36: =SUM(사업검토!#REF!) -> #REF! | G36: =SUM(사업검토!#REF!) -> #REF! | H36: =SUM(사업검토!#REF!) -> #REF! | I36: =SUM(사업검토!#REF!) -> #REF!
B37: 자기자본 조달 | E37: =SUM(F37:N37) -> #REF! | F37: =SUM(사업검토!#REF!) -> #REF! | G37: =SUM(사업검토!#REF!) -> #REF! | H37: =SUM(사업검토!#REF!) -> #REF! | I37: =SUM(사업검토!#REF!) -> #REF! | J37: =SUM(사업검토!#REF!) -> #REF!
B38: CASH FLOW | E38: =SUM(F38:N38) -> #REF! | F38: =SUM(사업검토!AD146) -> -5305489.4 | G38: =SUM(사업검토!AE146:AR146) -> -66750009 | H38: =SUM(사업검토!AS146:BD146) -> -61958016 | I38: =SUM(사업검토!BE146:BP146) -> 2.7098019e+08 | J38: =SUM(사업검토!#REF!) -> #REF!
B40: IRR | E40: =IRR(F38:N38) -> #VALUE!
B42: ■ 민감도 분석
B44: 1) 매각가 | I44: 2) 공사비
...

Sheet English
B1: ■ CASH-FLOW
Q2: (㎡, KRW1,000)
E3: Total | F3: Y+0 | G3: 1 | H3: =G3+1 -> 2 | I3: =H3+1 -> 3 | J3: =I3+1 -> 4 | K3: =J3+1 -> 5 | L3: =K3+1 -> 6 | M3: =L3+1 -> 7 | N3: =M3+1 -> 8 | O3: =N3+1 -> 9 | Q3: Remark
F4: Development | J4: Operation
F5: 39661 | G5: =F5+31 -> 39692 | H5: =G5+365.25 -> 40057.25 | I5: =H5+365.25 -> 40422.5 | J5: =I5+365.25 -> 40787.75 | K5: =J5+365.25 -> 41153 | L5: =K5+365.25 -> 41518.25 | M5: =L5+365.25 -> 41883.5 | N5: =M5+365.25 -> 42248.75 | O5: =N5+365.25 -> 42614
G6: =G5+364 -> 40056 | H6: =H5+364 -> 40421.25 | I6: =I5+364 -> 40786.5 | J6: =J5+364 -> 41151.75 | K6: =K5+364 -> 41517 | L6: =L5+364 -> 41882.25 | M6: =M5+364 -> 42247.5 | N6: =N5+364 -> 42612.75 | O6: =O5+364 -> 42978
B7: Revenue (A) | C7: =사업검토!#REF! -> #REF! | E7: =SUM(F7:M7) -> #REF! | F7: =SUM(사업검토!#REF!) -> #REF! | G7: =SUM(사업검토!#REF!) -> #REF! | H7: =SUM(사업검토!#REF!) -> #REF! | I7: =SUM(사업검토!#REF!) -> #REF! | J7: =SUM(사업검토!#REF!) -> #REF!
C8: =사업검토!#REF! -> #REF! | E8: =SUM(F8:M8) -> #REF! | F8: =SUM(사업검토!#REF!) -> #REF! | G8: =SUM(사업검토!#REF!) -> #REF! | H8: =SUM(사업검토!#REF!) -> #REF! | I8: =SUM(사업검토!#REF!) -> #REF! | J8: =SUM(사업검토!#REF!) -> #REF!
C9: Office | E9: 2.1572021e+08 | F9: 0 | G9: 0 | H9: 0 | I9: 2.1572021e+08 | J9: 0
C10: Retail | E10: 43200911 | F10: 0 | G10: 0 | H10: 0 | I10: 43200911 | J10: 0
C11: =사업검토!#REF! -> #REF! | E11: 0 | F11: 0 | G11: 0 | H11: 0 | I11: 0 | J11: 0
C12: =사업검토!#REF! -> #REF! | E12: 0 | F12: 0 | G12: 0 | H12: 0 | I12: 0 | J12: 0
C13: Sub Total | E13: 2.5892112e+08 | F13: 0 | G13: 0 | H13: 0 | I13: 2.5892112e+08 | J13: 0
B14: VAT (B) | E14: 12946056 | F14: 0 | G14: 0 | H14: 0 | I14: 12946056 | J14: 0
B15: Other Revenue (C) | E15: 0 | F15: 0 | G15: 0 | H15: 0 | I15: 0 | J15: 0
B16: Total (A-B+C) | E16: 2.4597507e+08 | F16: 0 | G16: 0 | H16: 0 | I16: 2.4597507e+08 | J16: 0
B17: Cost | C17: Land | E17: -1.2430759e+08 | F17: -9636122.1 | G17: -1.1467147e+08 | H17: 0 | I17: 0 | J17: 0 | Q17: Acquisition Cost, Appraisal, Broker Fee
C18: Construction Hard Cost | E18: -52413867 | F18: 0 | G18: -6390637.3 | H18: -23204511 | I18: -22818719 | J18: 0 | Q18: Demolition
C19: Construction Soft Cost | E19: -2200829.6 | F19: -129460.56 | G19: -1359335.9 | H19: -291286.26 | I19: -420746.83 | J19: 0 | Q19: A&E
C20: Selling Expense | E20: -2459750.7 | F20: 0 | G20: 0 | H20: 0 | I20: -2459750.7 | J20: 0
C21: Others & Interest on Loan | E21: -36520221 | F21: -2702.7027 | G21: -11100428 | H21: -9820607.6 | I21: -15596483 | J21: 0 | Q21: Interest, Tax. Others
C22: Contingency | E22: -1000000 | F22: -27027.027 | G22: -324324.32 | H22: -324324.32 | I22: -324324.32 | J22: 0
C23: Sub Total | E23: -2.1890226e+08 | F23: -9795312.4 | G23: -1.3384619e+08 | H23: -33640729 | I23: -41620023 | J23: 0
C24: Gap Financing | E24: -7146350.7 | F24: -30610.351 | G24: -1358269 | H24: -2365453.3 | I24: -3392018.1 | J24: 0
C25: Operating Expense | E25: -3689626 | F25: -99719.622 | G25: -1196635.5 | H25: -1196635.5 | I25: -1196635.5 | J25: 0
C26: Total | E26: -2.2973824e+08 | F26: -9925642.3 | G26: -1.364011e+08 | H26: -37202818 | I26: -46208677 | J26: 0
B27: Loan | C27: Loan | D27: Land | E27: 1.0328388e+08 | F27: 0 | G27: 1.0328388e+08 | H27: 0 | I27: 0 | J27: 0
D28: Financing | E28: 52218533 | F28: 0 | G28: 16203520 | H28: 17670384 | I28: 18344629 | J28: 0
D29: Sub Total | E29: 1.5550241e+08 | F29: 0 | G29: 1.194874e+08 | H29: 17670384 | I29: 18344629 | J29: 0
C30: Interest Payment | D30: Land | E30: 0 | F30: 0 | G30: 0 | H30: 0 | I30: 0 | J30: 0
D31: Financing | E31: 0 | F31: 0 | G31: 0 | H31: 0 | I31: 0 | J31: 0
D32: Sub Total | E32: 0 | F32: 0 | G32: 0 | H32: 0 | I32: 0 | J32: 0
C33: Repayment | E33: -1.5550241e+08 | F33: 0 | G33: 0 | H33: 0 | I33: -1.5550241e+08
B34: Equity | E34: -67578576 | F34: -9925642.3 | G34: -16913700 | H34: -19532434 | I34: -21206799 | J34: 0
B35: CASH FLOW | E35: 16236832 | F35: -9925642.3 | G35: -16913700 | H35: -19532434 | I35: 62608609 | J35: 0
B37: IRR | E37: =IRR(F35:N35) -> 0.17703792
B39: ■ 민감도 분석
B41: 1) 매각가 | I41: 2) 공사비
B43: 매입가격(천원) | E43: 매각가 | I43: 매입가격(천원) | L43: 공사비
B44: =$E$37 -> 0.17703792 | C44: =D44-500 -> 10000 | D44: =E44-500 -> 10500 | E44: 11000 | F44: =E44+500 -> 11500 | G44: =F44+500 -> 12000 | I44: =$E$37 -> 0.17703792 | J44: =K44-500 -> 4000 | K44: =L44-500 -> 4500 | L44: 5000 | M44: =L44+500 -> 5500 | N44: =M44+500 -> 6000
...

Sheet 개발부담금
A1: ■ 개발부담금
B3: - 토지로부터 발생되는 개발이익을 환수하여 이를 적정하게 배분함으로써 토지에 대한 투기 방지
B4: - 택지개발사업, 공업단지조성사업, 관광단지조성사업, 유통단지조성사업, 온천개발사업 화룸터미널개발사업 골프장개발사업 등 30개 사업
B5: - 주택사업, 도시환경정비사업
B6: - 사업승인시부터 부고대상임을 고지, 준공후 3개월내 부과, 부과후 6개월내 납부
B8: 개발부담금 = 토지개발이익(사업종료시점지가 - 사업개시시점 지가 - 개발비용 - 정상 지가 상승분) × 부과율 25%
B10: 결정금액 | C10: =0 -> 0
B12: □ 면적
B13: 구 분 | C13: 면 적
B14: 시행면적 | C14: =사업검토!E6 -> 60663.8 | D14: =C14*0.3025 -> 18350.8
B15: 기부채납 (기존공공용지 및 공원부지) | C15: =사업검토!E7 -> 0 | D15: =C15*0.3025 -> 0
B16: 제척면적(기부채납에 포함) | C16: =사업검토!E8 -> 0 | D16: =C16*0.3025 -> 0
B17: 대지면적 | C17: =사업검토!E9 -> 60663.8 | D17: =C17*0.3025 -> 18350.8
B19: □ 사업종료시점 지가 = 현재지가 + 개발후 지가상승분
B21: 구 분 | C21: 금 액 | D21: 비 고
B22: 사업개시시점 지가 | C22: =C43*C14 -> 0 | D22: 현재 지가
B23: 인근지역 공시지가 | C23: =C54 -> 0
C24: =C23/0.3025 -> 0
B25: 개발후 지가 상승분 | C25: =C22*(AVERAGE(E41:E42)*C35/12) -> 0 | D25: 현재지가 X 지가 평균 상승률 X 기간(년)
B26: 사업종료시점 지가 | C26: =C22+C25 -> 0
B28: 구 분 | C28: 금 액 | D28: 비 고
B29: 개발비용 (철거비, 토지조성비 등) | C29: =사업검토!M80*1000 -> 18350799500
B30: 기부채납 (공원 및 공공용지 등) | C30: =C15*C41 -> 0
B32: 구 분 | C32: 금 액 | D32: 비 고
B33: 정상 지가 상승분 | C33: =C22*(AVERAGE(F52)*C35/12) -> #DIV/0! | D33: 현재지가 X 인근지역 평균 상승률 X 기간(년)
B35: 공사기간 | C35: =사업검토!L12 -> 40
B36: 대상지 평균 상승률 | C36: =E48 -> #DIV/0!
B37: 인근지역 공시지가 변동율 | C37: =F52 -> #DIV/0!
B39: □ 지구내 공시지가
B40: 년도 | C40: 공시지가(원/㎡) | D40: 증감(원) | E40: 변동율 | F40: 비고
B41: 46753 | C41: =C42*(1+$E$42) -> 0 | D41: =C41-C42 -> 0 | E41: 0
B42: 46388 | C42: =C43*(1+$E$42) -> 0 | D42: =C42-C43 -> 0 | E42: 0
B43: 46023 | D43: =C43-C44 -> 0 | E43: 0 | F43: 착공 | H43: =C43*40% -> 0
B44: 45658 | D44: =C44-C45 -> 0 | E44: =((C44/C45)-1) -> #DIV/0! | H44: =C44*40% -> 0
B45: 45292 | D45: =C45-C46 -> 0 | E45: =((C45/C46)-1) -> #DIV/0! | H45: =C45*40% -> 0
B46: 44927 | D46: =C46-C47 -> 0 | E46: =((C46/C47)-1) -> #DIV/0! | H46: =C46*40% -> 0
B47: 44562 | H47: =C47*40% -> 0
D48: 평균변동율 | E48: =SUM(E43:E46)/4 -> #DIV/0!
B50: □ 인근지역 공시지가
B51: 년도 | C51: 공시지가(원/㎡) | D51: 증감(원) | E51: 변동율 | F51: 비고
...

Sheet 토지조서
A1: 토지조서
G2: (천원)
A3: 연번 | B3: 지번 | C3: 면적 | E3: 공시지가 | G3: 시가표준 | H3: 수수료 | L3: 작성 예시
C4: ㎡ | D4: 평 | E4: ㎡당 | F4: 평당가 | L4: 연번 | M4: 지번 | N4: 면적 | P4: 공시지가 | R4: 시가표준 | S4: 수수료
A5: 1 | B5: 1189-1 | C5: 106.1 | D5: =C5*0.3025 -> 32.09525 | E5: =(6909000*1.25)/1000 -> 8636.25 | F5: =E5/0.3025 -> 28549.587 | G5: =C5*E5 -> 916306.12 | H5: =C680 -> 761 | N5: ㎡ | O5: 평 | P5: ㎡당 | Q5: 평당가
A6: 2 | B6: 1189-2 | C6: 129.3 | D6: =C6*0.3025 -> 39.11325 | E6: =(6835000*1.25)/1000 -> 8543.75 | F6: =E6/0.3025 -> 28243.802 | G6: =C6*E6 -> 1104706.9 | H6: =C72 -> 89.2 | L6: 1 | M6: 680-24 | N6: 1489.5㎡ | O6: 450.57 | P6: 11170 | Q6: 36926 | R6: 16637715 | S6: 4897
A7: 3 | B7: 1189-3 | C7: 120.2 | D7: =C7*0.3025 -> 36.3605 | E7: =(3676000*1.25)/1000 -> 4595 | F7: =E7/0.3025 -> 15190.083 | G7: =C7*E7 -> 552319 | H7: =C87 -> 89
A8: 4 | B8: 1189-4 | C8: 109.6 | D8: =C8*0.3025 -> 33.154 | E8: =(3572000*1.25)/1000 -> 4465 | F8: =E8/0.3025 -> 14760.331 | G8: =C8*E8 -> 489364 | H8: =C102 -> 91.9
A9: 5 | B9: 1189-5 | C9: 93.5 | D9: =C9*0.3025 -> 28.28375 | E9: =(4710000*1.25)/1000 -> 5887.5 | F9: =E9/0.3025 -> 19462.81 | G9: =C9*E9 -> 550481.25 | H9: =C117 -> 87.5
A10: 6 | B10: 1189-6 | C10: 90.3 | D10: =C10*0.3025 -> 27.31575 | E10: =(3640000*1.25)/1000 -> 4550 | F10: =E10/0.3025 -> 15041.322 | G10: =C10*E10 -> 410865 | H10: =C132 -> 91
A11: 7 | B11: 1189-7 | C11: 86.2 | D11: =C11*0.3025 -> 26.0755 | E11: =(3640000*1.25)/1000 -> 4550 | F11: =E11/0.3025 -> 15041.322 | G11: =C11*E11 -> 392210 | H11: =C147 -> 85.7
A12: 8 | B12: 1189-8 | C12: 89.1 | D12: =C12*0.3025 -> 26.95275 | E12: =(3640000*1.25)/1000 -> 4550 | F12: =E12/0.3025 -> 15041.322 | G12: =C12*E12 -> 405405 | H12: =C162 -> 90.9
A13: 9 | B13: 1189-9 | C13: 87.4 | D13: =C13*0.3025 -> 26.4385 | E13: =(3640000*1.25)/1000 -> 4550 | F13: =E13/0.3025 -> 15041.322 | G13: =C13*E13 -> 397670 | H13: =C177 -> 88.3
A14: 10 | B14: 1189-10 | C14: 102.1 | D14: =C14*0.3025 -> 30.88525 | E14: =(6835000*1.25)/1000 -> 8543.75 | F14: =E14/0.3025 -> 28243.802 | G14: =C14*E14 -> 872316.88 | H14: =C192 -> 90.1
A15: 11 | B15: 1189-11 | C15: 103.7 | D15: =C15*0.3025 -> 31.36925 | E15: =(6835000*1.25)/1000 -> 8543.75 | F15: =E15/0.3025 -> 28243.802 | G15: =C15*E15 -> 885986.88 | H15: =C207 -> 175.6
A16: 12 | B16: 1189-12 | C16: 96.3 | D16: =C16*0.3025 -> 29.13075 | E16: =(3712000*1.25)/1000 -> 4640 | F16: =E16/0.3025 -> 15338.843 | G16: =C16*E16 -> 446832 | H16: =C222 -> 88.5
A17: 13 | B17: 1189-13 | C17: 92.3 | D17: =C17*0.3025 -> 27.92075 | E17: =(3712000*1.25)/1000 -> 4640 | F17: =E17/0.3025 -> 15338.843 | G17: =C17*E17 -> 428272 | H17: =C237 -> 88.9
A18: 14 | B18: 1189-14 | C18: 90.7 | D18: =C18*0.3025 -> 27.43675 | E18: =(3712000*1.25)/1000 -> 4640 | F18: =E18/0.3025 -> 15338.843 | G18: =C18*E18 -> 420848 | H18: =C253 -> 89.4
A19: 15 | B19: 1189-15 | C19: 90.2 | D19: =C19*0.3025 -> 27.2855 | E19: =(3712000*1.25)/1000 -> 4640 | F19: =E19/0.3025 -> 15338.843 | G19: =C19*E19 -> 418528 | H19: =C268 -> 87.5
A20: 16 | B20: 1189-16 | C20: 89.6 | D20: =C20*0.3025 -> 27.104 | E20: =(3712000*1.25)/1000 -> 4640 | F20: =E20/0.3025 -> 15338.843 | G20: =C20*E20 -> 415744 | H20: =C283 -> 88.7
A21: 17 | B21: 1189-17 | C21: 85 | D21: =C21*0.3025 -> 25.7125 | E21: =(3712000*1.25)/1000 -> 4640 | F21: =E21/0.3025 -> 15338.843 | G21: =C21*E21 -> 394400 | H21: =C298 -> 88.2
A22: 18 | B22: 1189-18 | C22: 89.3 | D22: =C22*0.3025 -> 27.01325 | E22: =(3712000*1.25)/1000 -> 4640 | F22: =E22/0.3025 -> 15338.843 | G22: =C22*E22 -> 414352 | H22: =C313 -> 89.7
A23: 19 | B23: 1189-19 | C23: 109.2 | D23: =C23*0.3025 -> 33.033 | E23: =(3608000*1.25)/1000 -> 4510 | F23: =E23/0.3025 -> 14909.091 | G23: =C23*E23 -> 492492 | H23: =C328 -> 86.5
A24: 20 | B24: 1189-20 | C24: 94 | D24: =C24*0.3025 -> 28.435 | E24: =(3608000*1.25)/1000 -> 4510 | F24: =E24/0.3025 -> 14909.091 | G24: =C24*E24 -> 423940 | H24: =C343 -> 90.8
A25: 21 | B25: 1189-21 | C25: 142 | D25: =C25*0.3025 -> 42.955 | E25: =(1201000*1.25)/1000 -> 1501.25 | F25: =E25/0.3025 -> 4962.8099 | G25: =C25*E25 -> 213177.5 | H25: =C358 -> 87.8
A26: 22 | B26: 1188-1 | C26: 166.2 | D26: =C26*0.3025 -> 50.2755 | E26: =(3629000*1.25)/1000 -> 4536.25 | F26: =E26/0.3025 -> 14995.868 | G26: =C26*E26 -> 753924.75 | H26: =C373 -> 90.3
A27: 23 | B27: 1188-2 | C27: 85.9 | D27: =C27*0.3025 -> 25.98475 | E27: =(3640000*1.25)/1000 -> 4550 | F27: =E27/0.3025 -> 15041.322 | G27: =C27*E27 -> 390845 | H27: =C388 -> 89.4
A28: 24 | B28: 1188-3 | C28: 87.9 | D28: =C28*0.3025 -> 26.58975 | E28: =(3640000*1.25)/1000 -> 4550 | F28: =E28/0.3025 -> 15041.322 | G28: =C28*E28 -> 399945 | H28: =C403 -> 87.5
A29: 25 | B29: 1188-4 | C29: 87.2 | D29: =C29*0.3025 -> 26.378 | E29: =(3640000*1.25)/1000 -> 4550 | F29: =E29/0.3025 -> 15041.322 | G29: =C29*E29 -> 396760 | H29: =C418 -> 88.1
A30: 26 | B30: 1188-5 | C30: 87 | D30: =C30*0.3025 -> 26.3175 | E30: =(3640000*1.25)/1000 -> 4550 | F30: =E30/0.3025 -> 15041.322 | G30: =C30*E30 -> 395850 | H30: =C433 -> 87.6
A31: 27 | B31: 1188-6 | C31: 91.5 | D31: =C31*0.3025 -> 27.67875 | E31: =(3640000*1.25)/1000 -> 4550 | F31: =E31/0.3025 -> 15041.322 | G31: =C31*E31 -> 416325 | H31: =C448 -> 89.7
A32: 28 | B32: 1188-7 | C32: 89.8 | D32: =C32*0.3025 -> 27.1645 | E32: =(3640000*1.25)/1000 -> 4550 | F32: =E32/0.3025 -> 15041.322 | G32: =C32*E32 -> 408590 | H32: =C463 -> 89.6
A33: 29 | B33: 1188-8 | C33: 88.6 | D33: =C33*0.3025 -> 26.8015 | E33: =(3640000*1.25)/1000 -> 4550 | F33: =E33/0.3025 -> 15041.322 | G33: =C33*E33 -> 403130 | H33: =C478 -> 91
A34: 30 | B34: 1188-9 | C34: 87.5 | D34: =C34*0.3025 -> 26.46875 | E34: =(3640000*1.25)/1000 -> 4550 | F34: =E34/0.3025 -> 15041.322 | G34: =C34*E34 -> 398125 | H34: =C493 -> 92.1
A35: 31 | B35: 1188-10 | C35: 86.5 | D35: =C35*0.3025 -> 26.16625 | E35: =(3640000*1.25)/1000 -> 4550 | F35: =E35/0.3025 -> 15041.322 | G35: =C35*E35 -> 393575 | H35: =C508 -> 90.6
A36: 32 | B36: 1188-11 | C36: 91.2 | D36: =C36*0.3025 -> 27.588 | E36: =(3640000*1.25)/1000 -> 4550 | F36: =E36/0.3025 -> 15041.322 | G36: =C36*E36 -> 414960 | H36: =C509 -> 88.5
A37: 33 | B37: 1188-12 | C37: 84.9 | D37: =C37*0.3025 -> 25.68225 | E37: =(6835000*1.25)/1000 -> 8543.75 | F37: =E37/0.3025 -> 28243.802 | G37: =C37*E37 -> 725364.38 | H37: =C510 -> 90.6
A38: 34 | B38: 1188-13 | C38: 82.4 | D38: =C38*0.3025 -> 24.926 | E38: =(6835000*1.25)/1000 -> 8543.75 | F38: =E38/0.3025 -> 28243.802 | G38: =C38*E38 -> 704005 | H38: =C511 -> 86.8
A39: 35 | B39: 1188-14 | C39: 88.9 | D39: =C39*0.3025 -> 26.89225 | E39: =(3570000*1.25)/1000 -> 4462.5 | F39: =E39/0.3025 -> 14752.066 | G39: =C39*E39 -> 396716.25 | H39: =C498 -> 497.4
A40: 36 | B40: 1188-15 | C40: 88.7 | D40: =C40*0.3025 -> 26.83175 | E40: =(3712000*1.25)/1000 -> 4640 | F40: =E40/0.3025 -> 15338.843 | G40: =C40*E40 -> 411568 | H40: =C513 -> 176.5
...

Sheet 세금
A2: ■ | B2: 토지취득과세 | E2: 중과세의 경우
B3: 취득세 | C3: 취득가액의 | D3: 0.04 | E3: 사치성재산*, 과밀억제권역 5년 미만 법인의 토지 취득 : 12% (3배)
B4: 농어촌특별세 | C4: 취득가액의 | D4: 0.002 | E4: 좌동
B5: 교육세 | C5: 취득가액의 | D5: 0.004 | E5: 좌동
B6: 일반세율 | C6: 취득가액의 | D6: =SUM(D3:D5) -> 0.046
B7: * 사치성 재산 : 별장, 골프장, 고급오락장, 고급주택, 고급선박
B8: 유무유흥주점 : 카바레, 나이트 크럽, 고고크럽, 디스코 클럽, 룸쌀롱 (객실 2이상)
B9: 요정영업장소 (유흥접객원이 있는 경우)
B10: 특수목욕장 중 증기탕
B12: 토지매입비 | C12: =사업검토!M70 -> 0 | D12: 천원
B13: 결정세액 | C13: =C12*D6 -> 0 | D13: 천원
A16: ■ | B16: 토지보유과세
B18: 면적 | C18: ㎡ | D18: 평 | E18: 과세기준일 : 매년 6월1일
C19: =토지조서!C38 -> 82.4 | D19: =토지조서!D38 -> 24.926 | E19: 납부일 : 매년 9월
B20: 공시지가(천원) | C20: =토지조서!E38 -> 8543.75 | D20: =토지조서!F38 -> 28243.802 | E20: - 7월 : 재산세(건축물) + 재산세(주택) 1/2
B21: 시가표준액 | C21: =PRODUCT(C19:C20) -> 704005 | D21: =PRODUCT(D19:D20) -> 704005 | E21: - 9월 : 재산세(토지) + 재산세(주택) 1/2
A23: 1) | B23: 재산세
B25: 재산세 = 과세표준(시가표준액 X 공정시장가액비율) X 세율
B27: 구 분 | C27: 금액(천원) | D27: 비고
B28: 시가표준액 | C28: =C21 -> 704005 | D28: 별도합산과세
B29: 공정시장가액 비율 | C29: 0.7
B30: 과세표준 | C30: =C28*C29 -> 492803.5
B31: 세율 | C31: 0.004 | D31: 280만+10억원 초과금액 0.4%
B32: 재산세액 | C32: =2800+(C30-1000000)*4/1000 -> 771.214
B33: 공제 제산세액
B34: 결정세액 | C34: =C32-C33 -> 771.214
A36: 2) | B36: 종합부동산세
B38: 종합부동산세 = 과세표준(시가표준액 X 공정시장가액비율) X 세율
B40: 구 분 | C40: 금액(천원) | D40: 비고
B41: 시가표준액 | C41: =C21 -> 704005
B42: 공제금액 | C42: 8000000 | D42: 별도합산
B43: 공정시장가액 비율 | C43: 0.6
B44: 과세표준 | C44: =(C41-C42)*C43 -> -4377597
B45: 세율 | C45: 200억원 이하 0.5%
C46: 400억원 이하 0.6% | D46: 누진공제 2,000만원
C47: 600억원 초과 0.7% | D47: 누진공제 6,000만원
B48: 종합부동산세액 | C48: =IF(C44<20000000,C44*0.5%,(IF(C44<40000000,C44*0.6%-20000,C44*0.7%-60000))) -> -21887.985
B49: 공제 제산세액 | C49: =C34*C30*C29*C31/C32 -> 1379.8498 | D49: 국세청 참고
B50: 결정세액 | C50: =IF((C48-C49)<E460,0,(C48-C49)) -> 0
A85: ■ | B85: 채권매각손 | D85: 구분(주거전용이외:1, 주거전용:0)
...
